Workbook

Sheet Cover
A1: BINGHATTI HOLDING
A2: Escrow release against debt maturities — a register-based liquidity model
A4: Prepared by | B4: DPI
A5: Register read date | B5: =Simulator!$C$3 -> 46275
A6: Financials as at | B6: 30 June 2026 (interim), FY2025 audited
A7: Currency and units | B7: AED millions, unless a cell says otherwise
A8: Active scenario | B8: =Scenarios!$C$3 -> Base
A10: THE QUESTION
A11: Binghatti has AED 11,623m of sukuk and bank debt maturing between now and 2031. Can cash released from construction escrow, net of the cost of building the towers and of servicing the debt, meet each maturity as it falls?
A13: WHAT THE PUBLIC REGISTER CURRENTLY SUPPORTS — A CONDITIONAL FINDING, NOT A VERDICT
A14: ="On the data the Dubai Land Department register holds today, and on three assumptions set out below that we have had to derive rather than obtain, "&COUNTIF($F$16:$F$23,"<1")&" of the eight maturities to 2031 are not met from modelled cash, short by AED "&TEXT($G$24,"#,##0")&_xlfn._LONGTEXT(" m in total. Read that as conditional. Each of the three assumptions, moved on its own within a plausible range, reverses it: see the box below. The table is ordered by maturity date; cash available is the modelled balance in the maturity month before tha","t principal is paid, after the cost of completing the towers and all profit and interest payments. Sukuk carry their actual coupons; the bank rate is backed out of reported finance cost.") -> On the data the Dubai Land Department register holds today, and on three assumptions set out below that we have had to derive rather than obtain, 2 of the eight maturities to 2031 are not met from modelled cash, short by AED 551 m in total. Read that as conditional. Each of the three assumptions, moved on its own within a plausible range, reverses it: see the box below. The table is ordered by maturity date; cash available is the modelled balance in the maturity month before that principal is paid, after the cost of completing the towers and all profit and interest payments. Sukuk carry their actual coupons; the bank rate is backed out of reported finance cost.
A15: Instrument | B15: Maturity | C15: Amount | D15: Rate | E15: Cash available | F15: Coverage | G15: Shortfall | H15: Rate source
A16: =INDEX('Cash flow'!$A$94:$A$101,MATCH($B16,'Cash flow'!$B$94:$B$101,0)) -> Secured bank debt — due H2 2026 | B16: =SMALL('Cash flow'!$B$94:$B$101,ROW()-15) -> 46387 | C16: =INDEX('Cash flow'!$C$94:$C$101,MATCH($B16,'Cash flow'!$B$94:$B$101,0)) -> 1031.9725 | D16: =INDEX('Cash flow'!$D$32:$D$39,MATCH($B16,'Cash flow'!$B$94:$B$101,0)) -> 0.097691709 | E16: =INDEX('Cash flow'!$E$94:$E$101,MATCH($B16,'Cash flow'!$B$94:$B$101,0)) -> 843.54181 | F16: =INDEX('Cash flow'!$F$94:$F$101,MATCH($B16,'Cash flow'!$B$94:$B$101,0)) -> 0.81740725 | G16: =INDEX('Cash flow'!$G$94:$G$101,MATCH($B16,'Cash flow'!$B$94:$B$101,0)) -> 188.43069 | H16: =INDEX('Cash flow'!$H$32:$H$39,MATCH($B16,'Cash flow'!$B$94:$B$101,0)) -> derived, section 3b
A17: =INDEX('Cash flow'!$A$94:$A$101,MATCH($B17,'Cash flow'!$B$94:$B$101,0)) -> 9.625% sukuk due 28 Feb 2027 | B17: =SMALL('Cash flow'!$B$94:$B$101,ROW()-15) -> 46446 | C17: =INDEX('Cash flow'!$C$94:$C$101,MATCH($B17,'Cash flow'!$B$94:$B$101,0)) -> 1836.25 | D17: =INDEX('Cash flow'!$D$32:$D$39,MATCH($B17,'Cash flow'!$B$94:$B$101,0)) -> 0.09625 | E17: =INDEX('Cash flow'!$E$94:$E$101,MATCH($B17,'Cash flow'!$B$94:$B$101,0)) -> 1473.7013 | F17: =INDEX('Cash flow'!$F$94:$F$101,MATCH($B17,'Cash flow'!$B$94:$B$101,0)) -> 0.80256025 | G17: =INDEX('Cash flow'!$G$94:$G$101,MATCH($B17,'Cash flow'!$B$94:$B$101,0)) -> 362.54875 | H17: =INDEX('Cash flow'!$H$32:$H$39,MATCH($B17,'Cash flow'!$B$94:$B$101,0)) -> actual coupon, offering circular
A18: =INDEX('Cash flow'!$A$94:$A$101,MATCH($B18,'Cash flow'!$B$94:$B$101,0)) -> Secured bank debt — due H1 2027 | B18: =SMALL('Cash flow'!$B$94:$B$101,ROW()-15) -> 46568 | C18: =INDEX('Cash flow'!$C$94:$C$101,MATCH($B18,'Cash flow'!$B$94:$B$101,0)) -> 690.43 | D18: =INDEX('Cash flow'!$D$32:$D$39,MATCH($B18,'Cash flow'!$B$94:$B$101,0)) -> 0.097691709 | E18: =INDEX('Cash flow'!$E$94:$E$101,MATCH($B18,'Cash flow'!$B$94:$B$101,0)) -> 7244.6114 | F18: =INDEX('Cash flow'!$F$94:$F$101,MATCH($B18,'Cash flow'!$B$94:$B$101,0)) -> 10.492898 | G18: =INDEX('Cash flow'!$G$94:$G$101,MATCH($B18,'Cash flow'!$B$94:$B$101,0)) -> 0 | H18: =INDEX('Cash flow'!$H$32:$H$39,MATCH($B18,'Cash flow'!$B$94:$B$101,0)) -> derived, section 3b
A19: =INDEX('Cash flow'!$A$94:$A$101,MATCH($B19,'Cash flow'!$B$94:$B$101,0)) -> Secured bank debt — due H2 2027 | B19: =SMALL('Cash flow'!$B$94:$B$101,ROW()-15) -> 46752 | C19: =INDEX('Cash flow'!$C$94:$C$101,MATCH($B19,'Cash flow'!$B$94:$B$101,0)) -> 1182.545 | D19: =INDEX('Cash flow'!$D$32:$D$39,MATCH($B19,'Cash flow'!$B$94:$B$101,0)) -> 0.097691709 | E19: =INDEX('Cash flow'!$E$94:$E$101,MATCH($B19,'Cash flow'!$B$94:$B$101,0)) -> 14295.373 | F19: =INDEX('Cash flow'!$F$94:$F$101,MATCH($B19,'Cash flow'!$B$94:$B$101,0)) -> 12.08865 | G19: =INDEX('Cash flow'!$G$94:$G$101,MATCH($B19,'Cash flow'!$B$94:$B$101,0)) -> 0 | H19: =INDEX('Cash flow'!$H$32:$H$39,MATCH($B19,'Cash flow'!$B$94:$B$101,0)) -> derived, section 3b
A20: =INDEX('Cash flow'!$A$94:$A$101,MATCH($B20,'Cash flow'!$B$94:$B$101,0)) -> Secured bank debt — due 2028 | B20: =SMALL('Cash flow'!$B$94:$B$101,ROW()-15) -> 46934 | C20: =INDEX('Cash flow'!$C$94:$C$101,MATCH($B20,'Cash flow'!$B$94:$B$101,0)) -> 1373.515 | D20: =INDEX('Cash flow'!$D$32:$D$39,MATCH($B20,'Cash flow'!$B$94:$B$101,0)) -> 0.097691709 | E20: =INDEX('Cash flow'!$E$94:$E$101,MATCH($B20,'Cash flow'!$B$94:$B$101,0)) -> 14322.187 | F20: =INDEX('Cash flow'!$F$94:$F$101,MATCH($B20,'Cash flow'!$B$94:$B$101,0)) -> 10.427397 | G20: =INDEX('Cash flow'!$G$94:$G$101,MATCH($B20,'Cash flow'!$B$94:$B$101,0)) -> 0 | H20: =INDEX('Cash flow'!$H$32:$H$39,MATCH($B20,'Cash flow'!$B$94:$B$101,0)) -> derived, section 3b
A21: =INDEX('Cash flow'!$A$94:$A$101,MATCH($B21,'Cash flow'!$B$94:$B$101,0)) -> 7.75% green sukuk due 2 Jul 2029 | B21: =SMALL('Cash flow'!$B$94:$B$101,ROW()-15) -> 47301 | C21: =INDEX('Cash flow'!$C$94:$C$101,MATCH($B21,'Cash flow'!$B$94:$B$101,0)) -> 1836.25 | D21: =INDEX('Cash flow'!$D$32:$D$39,MATCH($B21,'Cash flow'!$B$94:$B$101,0)) -> 0.0775 | E21: =INDEX('Cash flow'!$E$94:$E$101,MATCH($B21,'Cash flow'!$B$94:$B$101,0)) -> 13876.29 | F21: =INDEX('Cash flow'!$F$94:$F$101,MATCH($B21,'Cash flow'!$B$94:$B$101,0)) -> 7.5568632 | G21: =INDEX('Cash flow'!$G$94:$G$101,MATCH($B21,'Cash flow'!$B$94:$B$101,0)) -> 0 | H21: =INDEX('Cash flow'!$H$32:$H$39,MATCH($B21,'Cash flow'!$B$94:$B$101,0)) -> actual coupon, offering circular
A22: =INDEX('Cash flow'!$A$94:$A$101,MATCH($B22,'Cash flow'!$B$94:$B$101,0)) -> 8.125% sukuk due 7 Aug 2030 | B22: =SMALL('Cash flow'!$B$94:$B$101,ROW()-15) -> 47702 | C22: =INDEX('Cash flow'!$C$94:$C$101,MATCH($B22,'Cash flow'!$B$94:$B$101,0)) -> 1836.25 | D22: =INDEX('Cash flow'!$D$32:$D$39,MATCH($B22,'Cash flow'!$B$94:$B$101,0)) -> 0.08125 | E22: =INDEX('Cash flow'!$E$94:$E$101,MATCH($B22,'Cash flow'!$B$94:$B$101,0)) -> 11897.477 | F22: =INDEX('Cash flow'!$F$94:$F$101,MATCH($B22,'Cash flow'!$B$94:$B$101,0)) -> 6.4792249 | G22: =INDEX('Cash flow'!$G$94:$G$101,MATCH($B22,'Cash flow'!$B$94:$B$101,0)) -> 0 | H22: =INDEX('Cash flow'!$H$32:$H$39,MATCH($B22,'Cash flow'!$B$94:$B$101,0)) -> actual coupon, offering circular
A23: =INDEX('Cash flow'!$A$94:$A$101,MATCH($B23,'Cash flow'!$B$94:$B$101,0)) -> 8.375% sukuk due 12 Aug 2031 | B23: =SMALL('Cash flow'!$B$94:$B$101,ROW()-15) -> 48072 | C23: =INDEX('Cash flow'!$C$94:$C$101,MATCH($B23,'Cash flow'!$B$94:$B$101,0)) -> 1836.25 | D23: =INDEX('Cash flow'!$D$32:$D$39,MATCH($B23,'Cash flow'!$B$94:$B$101,0)) -> 0.08375 | E23: =INDEX('Cash flow'!$E$94:$E$101,MATCH($B23,'Cash flow'!$B$94:$B$101,0)) -> 9907.4408 | F23: =INDEX('Cash flow'!$F$94:$F$101,MATCH($B23,'Cash flow'!$B$94:$B$101,0)) -> 5.3954749 | G23: =INDEX('Cash flow'!$G$94:$G$101,MATCH($B23,'Cash flow'!$B$94:$B$101,0)) -> 0 | H23: =INDEX('Cash flow'!$H$32:$H$39,MATCH($B23,'Cash flow'!$B$94:$B$101,0)) -> actual coupon, offering circular
A24: Total | C24: =SUM(C16:C23) -> 11623.462 | D24: =IF(C24>0,SUMPRODUCT(C16:C23,D16:D23)/C24,"") -> 0.089474199 | G24: =SUM(G16:G23) -> 550.97944
A26: {=IF(COUNTIF($F$16:$F$23,"<1")=0,"No modelled shortfall on any maturity to 2031","Total shortfall, last affected maturity "&TEXT(MAX(($G$16:$G$23>0)*$B$16:$B$23),"mmm yyyy"))} -> Total shortfall, last affected maturity Feb 2027 | B26: =G24 -> 550.97944 | C26: AED m
A27: Maturities covered, of eight | B27: =COUNTIF($F$16:$F$23,">=1") -> 6 | C27: {=COUNTIF($F$16:$F$23,"<1")&IF(COUNTIF($F$16:$F$23,"<1")=1," not covered, first failing "," not covered, first failing ")&TEXT(MIN(IF($G$16:$G$23>0,$B$16:$B$23)),"mmm yyyy")} -> 2 not covered, first failing Dec 2026
A28: Deepest cash point on the path | B28: ='Cash flow'!$B$11 -> -362.54875 | C28: ="AED m, in "&TEXT('Cash flow'!$B$12,"mmm yyyy") -> AED m, in Feb 2027
A29: Cash at end 2027, once the handovers land | B29: ='Cash flow'!$B$13 -> 13112.828 | C29: ="AED m, after "&TEXT('Cash flow'!$D$89,"0")&" of the 32 live towers complete" -> AED m, after 24 of the 32 live towers complete
A31: THE THREE ASSUMPTIONS THAT EACH REVERSE THIS ON THEIR OWN
A32: Not three combined. Any one of them, moved alone within a range the evidence allows, covers every maturity and removes the shortfall entirely. None is a disclosed figure.
A33: Assumption | B33: Used here | C33: Reverses at | D33: Where it comes from, and what would settle it
A34: Register progress readings | B34: ='Cash flow'!$B$127&" of 32 towers on the 15 Jun read" -> 14 of 32 towers on the 15 Jun read | C34: +15 points | D34: The June dump showed Binghatti Apex at 45% certified two months after it had completed. Understated progress makes this model too pessimistic. A refreshed extract covering all 68 projects settles it and costs nothing but time.
A35: Cost to complete | B35: =TEXT(Scenarios!$F$15,"0.0%")&" of contracted value" -> 55.0% of contracted value | C35: =TEXT('Break-even'!$B$13,"0.0%") -> 52.5% | D35: Inferred from the reported gross margin of 44 to 45 per cent, not disclosed. Any real cost-to-complete data from the issuer replaces it.
A36: Cash received since 30 June | B36: ="AED "&TEXT(Dashboard!$D$5,"#,##0")&" m, register-supported" -> AED 293 m, register-supported | C36: AED 1,800 m as claimed | D36: The company's own figure, unsourced and untraceable to any filing. The register confirms one handover, not three. An investor relations enquiry settles it.
A38: HOW TO READ THIS
A39: {=_xlfn.LET(_xlpm.lastd,MAX(('Cash flow'!$G$94:$G$101>0)*'Cash flow'!$B$94:$B$101),"The shortfall sits on the two nearest maturities. Everything after "&TEXT(_xlpm.lastd,"mmm yyyy")&" is covered on this basis, because "&TEXT('Cash flow'!$D$89,"0")&" of the 32 live towers are modelled to complete during 2027, releasing AED "&TEXT('Cash flow'!$D$77,"#,##0")&_xlfn._LONGTEXT(" m of escrow in that year. The 2029, 2030 and 2031 sukuk are then met from cash accumulated in 2027 and 2028 rather than from new escrow, since release is nil from 2029 once the present pipeline is finished. So the back end depends on that handover wave a","rriving on something close to schedule, and the front end depends on the three assumptions above. Neither dependency is resolved by this workbook."))} -> The shortfall sits on the two nearest maturities. Everything after Feb 2027 is covered on this basis, because 24 of the 32 live towers are modelled to complete during 2027, releasing AED 27,419 m of escrow in that year. The 2029, 2030 and 2031 sukuk are then met from cash accumulated in 2027 and 2028 rather than from new escrow, since release is nil from 2029 once the present pipeline is finished. So the back end depends on that handover wave arriving on something close to schedule, and the front end depends on the three assumptions above. Neither dependency is resolved by this workbook.
A40: ="For contrast, the Dashboard's escrow headroom measure reads "&TEXT(Dashboard!$F$17,"0.00")&"x on the February 2027 sukuk. That measure credits the whole escrow release against debt and deducts neither the cost of building the towers nor any profit payments. It is a diagnostic, not the cash test; the table above is what binds." -> For contrast, the Dashboard's escrow headroom measure reads 3.79x on the February 2027 sukuk. That measure credits the whole escrow release against debt and deducts neither the cost of building the towers nor any profit payments. It is a diagnostic, not the cash test; the table above is what binds.
A50: CONTENTS
A51: How to use | B51: Start here. What you may change, what to read, how to interpret coverage.
A52: Model map | B52: How the sheets connect and the arithmetic step by step.
A53: Dashboard | B53: Escrow release against each maturity date, all four scenarios, with charts.
A54: Break-even | B54: How far handovers must slip, or cancellations rise, before coverage fails.
A55: Cash flow | B55: The full maturity stack to 2031 after construction cost and debt service. Read this one.
...

Sheet How to use
A1: HOW TO USE THIS MODEL
A2: Five minutes to the answer, then everything you may change and how to read the output.
A4: 1. THE SIX-MINUTE PATH
A5: Step | B5: Where | C5: What to do
A6: 1 | B6: Cover, rows 15 to 24 | C6: Read the maturity table. Eight instruments to 2031, ordered by date, with coverage and shortfall on each. Anything below 1.00x cannot be met from modelled cash. This is the answer; everything else explains it.
A7: 2 | B7: Cash flow, rows 64 to 77 | C7: Read the annual summary. Escrow release, retention, construction cost, debt service and closing cash by year to 2031. The lowest-cash row shows the trough inside each year, which the year-end balance hides.
A8: 3 | B8: Break-even | C8: Read how much handover delay or cancellation it takes to push coverage to 1.0x. This is the number to argue about.
A9: 4 | B9: Dashboard, rows 16 to 28 | C9: Read escrow coverage by maturity date across all four scenarios. Treat it as headroom before construction cost and debt service, not as the cash test; the caveat under the verdict band says so.
A10: 5 | B10: Dashboard, rows 66 to 76 | C10: Look at the ten towers doing the most work. Check certified % against registered date: a tower at 30% with its date already passed is not handing over in February.
A11: 6 | B11: Scenarios, cell B3 | C11: Type 1, 2, 3 or 4 to switch the active scenario. Everything on the Simulator, Dashboard and Cash flow follows that one cell. Break-even deliberately does not.
A12: 2. EVERY CELL YOU MAY CHANGE
A13: Blue text means an input. Black means a formula. Green means it is pulled from another sheet. If a cell is not listed here, changing it will break something.
A14: Sheet | B14: Cell | C14: Input | D14: Current | E14: Notes
A15: Scenarios | B15: B3 | C15: Active scenario, 1 to 4 | D15: =Scenarios!$B$3 -> 1 | E15: The master switch. 1 Base, 2 Delayed handovers, 3 Cancellation spike, 4 Price cut.
A16: Scenarios | B16: B5:E19 | C16: The fourteen assumptions, four columns | D16: — | E16: Overwrite any column with your own view. Column F resolves whichever is active; do not edit column F. Rows 15 to 19 are the newer inputs: cost to complete, EIBOR, bank margin, the refinancing toggle and the refinancing spread.
A17: Dashboard | B17: D5 | C17: Cash received since balance sheet date | D17: =Dashboard!$D$5 -> 292.5759 | E17: Defaults to zero. Fills the gap between the 30 Jun 2026 opening cash and the 10 Sep 2026 register date, which neither figure covers. The AED 1.8 bn attributed to three handovers is UNSOURCED in this workbook — see the gaps list on Ratings & sources — and entering it removes the entire modelled shortfall. Verify before use, and remember gross receipts are not all free cash.
A18: Dashboard | B18: B97 | C18: Dubai registered sales, all developers, 12m | D18: =Dashboard!$B$97 -> 187123 | E18: Denominator for the market-share calibration check only. Does not affect coverage or the cash flow.
A19: Simulator | B19: C3 | C19: Register read date | D19: =Simulator!$C$3 -> 46275 | E19: Month 1 of the monthly grids is the month after this date. Changing it re-dates the whole projection, on both the Simulator and the Cash flow sheet.
A20: Simulator | B20: D8:I39 | C20: Per-project register facts | D20: — | E20: Units, sold units, average ticket, certified %, registered completion date. Change these if you have a better read than the register.
A21: Debt | B21: Instrument rows 6 to 13 | C21: Amounts, coupons and maturity dates | D21: — | E21: Sukuk coupons are real and are used directly. Bank rows carry no coupon, so they take the derived rate. Adding a facility here flows through to the Dashboard, the Cash flow schedule and the coverage table.
A22: Break-even | B22: B28:B34, C27:I27 | C22: Grid axis ranges | D22: — | E22: Widen or narrow the delay and cancellation axes without touching the arithmetic. The working block below the grid re-derives itself.
A23: Cash flow | B23: B22 | C23: Bank rate basis | D23: ='Cash flow'!$B$22 -> Implied | E23: Type Implied to use the rate backed out of reported finance cost, or Quoted to use EIBOR plus the margin from the financing notes. The derivation is visible in section 3b of that sheet.
A24: Cash flow | B24: B25 and B26 | C24: Retention lag and horizon | D24: — | E24: Months after completion until RERA retention releases, and how many months the engine runs. The horizon is 64 so the 2031 sukuk falls inside it; shortening it will cut maturities off the end of the coverage table.
A26: 3. THE FOURTEEN ASSUMPTIONS, AND WHICH ONES ACTUALLY MOVE THE ANSWER
A27: Assumption | B27: Base | C27: Sensitivity | D27: Why it matters
A28: =Scenarios!$A$5 -> Handover delay added to every registered completion date (months) | B28: =Scenarios!$B$5 -> 0 | C28: High | D28: The single most powerful input. Every month of delay pushes certified progress, and therefore released cash, to the right. Switching to the Delayed scenario cuts the February release by roughly 45%.
A29: =Scenarios!$A$6 -> Months to completion for projects already past their registered date | B29: =Scenarios!$B$6 -> 6 | C29: High | D29: Applies to towers whose registered date has already passed, so the register gives no usable date. Several large towers sit here.
A30: =Scenarios!$A$7 -> Months to completion for projects with no registered date | B30: =Scenarios!$B$7 -> 24 | C30: Low | D30: Only four active towers carry no date at all, and at 24 months out they contribute almost nothing before February 2027.
A31: =Scenarios!$A$8 -> Cancellation rate — share of contracted value that is never collected | B31: =Scenarios!$B$8 -> 0 | C31: Medium | D31: Scales the remaining collections on every project linearly. Material, but less violent than delay because it does not change timing.
A32: =Scenarios!$A$9 -> Sell-through of unsold units before completion | B32: =Scenarios!$B$9 -> 0.6 | C32: Low | D32: Only 1,429 of 23,645 registered units are unsold, so future sales are a rounding item over this horizon.
A33: =Scenarios!$A$10 -> Price change on those future sales | B33: =Scenarios!$B$10 -> 0 | C33: Low | D33: Applies only to those same 1,429 unsold units.
A34: =Scenarios!$A$11 -> Share of price collected at sale (booking) | B34: =Scenarios!$B$11 -> 0.1 | C34: Medium | D34: Booking cash is already collected on sold units, so a higher booking share front-loads release. This is an assumption, not a filed term.
A35: =Scenarios!$A$12 -> Share of price collected at handover | B35: =Scenarios!$B$12 -> 0.3 | C35: High | D35: The handover instalment only lands at completion. A large handover share means cash arrives after February for any tower not finishing first.
A36: =Scenarios!$A$13 -> RERA escrow retention held until one year after completion | B36: =Scenarios!$B$13 -> 0.05 | C36: Low | D36: A flat 5% haircut on everything released.
A37: =Scenarios!$A$14 -> Maximum certified progress per month (percentage points) | B37: =Scenarios!$B$14 -> 8 | C37: Medium | D37: Binds on towers the model would otherwise certify implausibly fast. Lowering it slows release on the low-progress towers.
A38: Cost to complete, share of contracted value | B38: =Scenarios!$B$15 -> 0.55 | C38: High | D38: New, and now one of the two most powerful inputs. Escrow release is gross; this is what the towers cost to finish, deducted as certified progress is earned. The whole near-term shortfall moves with it. Derived from the reported gross margin, not disclosed.
A39: 3M EIBOR assumption for bank debt | B39: =Scenarios!$B$16 -> 0.042 | C39: Low | D39: Only used when the bank rate basis on the Cash flow sheet is set to Quoted. On the default Implied basis the bank rate is backed out of reported finance cost and this input is ignored.
A40: Bank margin over EIBOR | B40: =Scenarios!$B$17 -> 0.0238 | C40: Low | D40: As above: the quoted-basis alternative only. Midpoint of the 2.00 to 2.75 per cent range in the financing notes.
A41: Refinance sukuk at maturity, and the refinancing spread | B41: =Scenarios!$B$18 -> No | C41: High | D41: No is the hard test: every maturity must be met from cash. Switching to Yes rolls each sukuk instead of repaying it, which lifts February 2027 coverage above 1.0x and leaves only the December 2026 bank maturity short. The spread on the row below prices the replacement.
A43: 4. HOW TO READ THE TWO COVERAGE MEASURES
...

Sheet Model map
A1: HOW THE WORKBOOK HANGS TOGETHER
A2: Data flows in one direction. There are no circular references and no macros.
A4: 1. THE CHAIN
A5: Projects → Simulator → Dashboard → Cash flow → Cover with Scenarios feeding the Simulator and the Cash flow sheet, Debt and Financials supplying the liability and cash side, and Break-even stress-testing the whole thing independently of the active scenario
A7: Stage | B7: Sheet | C7: What it holds | D7: Feeds
A8: Source data | B8: Projects | C8: The full Dubai Land Department register extract: 68 projects, status, units, sold units, sales value, certified progress, completion dates, resale history. Row 73 totals it. | D8: Simulator (32 live projects), Dashboard section 4
A9: Assumptions | B9: Scenarios | C9: Fourteen assumptions in four named columns. Cell B3 selects which column is active; column F resolves it. Rows 15 to 19 are the cost, rate and refinancing inputs added for the cash flow build. | D9: Every formula on the Simulator and the Cash flow sheet
A10: Engine | B10: Simulator | C10: One row per live project. Columns E–I are register facts; J–U derive contracted value, collections and release to date; V–AW run 28 monthly columns; AY–BZ recompute all four scenarios at three checkpoint dates; CA is a rank key. | D10: Dashboard, Break-even
A11: Liabilities | B11: Debt | C11: Eight instruments with amounts and maturity dates, plus the maturity wall by year and covenant headroom. | D11: Dashboard (debt due by each date)
A12: Balance sheet | B12: Financials | C12: FY2024, FY2025 and H1 2026 filed figures, and leverage computed three ways depending on how much escrow you count as cash. | D12: Dashboard (free cash), Debt (covenant tests)
A13: Market | B13: Bonds | C13: Sukuk price, yield and spread at indicative bank quotes. | D13: Reference only — nothing downstream depends on it
A14: Headroom | B14: Dashboard | C14: Escrow coverage by maturity date across all four scenarios, the monthly release and running-cash path, the towers doing the most work, register-level calibration checks, and three charts. Coverage here is before construction cost and debt service. | D14: Cash flow (opening cash), Break-even (tie-out check)
A15: Cash test | B15: Cash flow | C15: A second escrow engine running 64 months instead of 28, so the 2029, 2030 and 2031 sukuk fall inside the horizon. Adds the two things the Dashboard leaves out: cost to complete, and debt service at each instrument's own rate. Section 3b backs the bank rate out of reported finance cost. Section 6 is the coverage table for all eight maturities. | D15: Cover (the maturity table and every headline figure on it)
A16: Stress | B16: Break-even | C16: Recomputes February 2027 coverage across a grid of handover delay against cancellation rate, independently of the active scenario. | D16: Cover (the 1.0x delay threshold)
A17: Provenance | B17: Ratings & sources | C17: Rating actions with agency rationale, filings with links, and four gaps we could not close. | D17: Nothing — documentation only
A19: 2. THE ARITHMETIC, STEP BY STEP
A20: Steps 1 to 8 are the escrow engine on the Simulator: one column each, applied to all 32 live projects. Steps 9 to 14 are the cash test on the Cash flow sheet, which extends the same arithmetic to 64 months and then deducts what the Dashboard leaves out. The figures in the fourth column are live.
A21: Step
A22: Size the contract | B22: J | C22: sold units × average registered ticket | D22: =Simulator!$J$40 -> 37362.292 | E22: Average ticket is registered off-plan sales value divided by number of sales. Resales of the same unit are not separated out.
A23: Adjust for cancellations and future sales | B23: P | C23: J × (1 − cancellation) + unsold units × ticket × sell-through × (1 + price change) | D23: =Simulator!$P$40 -> 40988.809 | E23: Higher than J on the Base scenario because 1,429 unsold units are credited at a 60% sell-through and no cancellations.
A24: Apply the payment plan | B24: U | C24: J × [ booking% + (1 − booking% − handover%) × certified% ] | D24: =Simulator!$U$40 -> 10645.046 | E24: Collected from buyers to date. Booking cash is in regardless of progress; the middle slice tracks certified construction; the handover slice only lands at completion.
A25: Convert collections to released cash | B25: Q | C25: U × min(1, certified% ) × (1 − retention) | D25: =Simulator!$Q$40 -> 4153.2762 | E25: This is the heart of the model. Escrow does not hand over what buyers paid: RERA releases funds in step with certified progress, less a 5% retention. Multiplying by progress a second time is why collections of AED 10.6 bn have released only AED 4.2 bn — and why roughly AED 10.2 bn is still sitting in escrow.
A26: Date the completion | B26: M | C26: registered date + delay; if the date has passed, today + 6 months; if there is no date, today + 24 months | D26: — | E26: A registered date in the past tells you nothing, so the model substitutes a fixed runway. Four active towers carry no date at all.
A27: Derive the build pace | B27: O | C27: min( cap, (100 − certified%) ÷ months to completion ) | D27: — | E27: Percentage points of certification per month. The cap stops the model certifying a tower faster than it could physically be built.
A28: Run it forward 28 months | B28: V:AW | C28: re-run steps 3 and 4 at certified% + pace × month, then subtract release to date; floored at zero | D28: =Simulator!$T$40 -> 34786.092 | E28: Oct 2026 to Jan 2029. Row 40 totals across projects, row 41 differences it into a monthly figure. The total shown here is cumulative release by Dec 2028.
A29: Snapshot the checkpoints | B29: R, S, T | C29: months 5, 15 and 27 of the grid | D29: =Simulator!$R$40 -> 10188.657 | E29: Feb 2027, Dec 2027, Dec 2028. The figure shown is the February 2027 release — the number the coverage ratio turns on.
A30: Test headroom | B30: Dashboard F17 | C30: ( free cash + release by the date ) ÷ debt due by the date | D30: =Dashboard!$F$17 -> 3.7916279 | E30: Measure A. Above 1.0x means modelled sources exceed the debt due on these assumptions. It deducts no construction cost and no debt service, so it is a headroom indicator, not a repayment test.
A31: Extend the horizon | B31: Cash flow C57:BN59 | C31: re-run the release arithmetic for 64 months instead of 28 | D31: ='Cash flow'!$B$104 -> 0 | E31: Oct 2026 to Jan 2032, so the 2029, 2030 and 2031 sukuk fall inside the model. The figure shown is the tie-out check: at month 28 this engine and the Simulator agree to zero.
A32: Recover the retention | B32: Cash flow row 61 | C32: retention × effective contracted value, credited 12 months after each tower completes | D32: =SUM('Cash flow'!$C$62:$BN$62) -> 2049.4404 | E32: The Simulator writes this off because it releases beyond its 28-month horizon. Over 64 months most of it comes back.
A33: Deduct the cost of building | B33: Cash flow row 63 | C33: effective contracted value × cost ratio × ( certified% now − certified% then ) | D33: =SUM('Cash flow'!$C$64:$BN$64) -> 15555.128 | E33: Incurred in step with certified progress, because that is what escrow releases against. Past cost is sunk and is not charged again. This is the deduction that reverses the near-term answer.
A34: Deduct debt service | B34: Cash flow rows 65 to 68 | C34: sukuk profit at actual coupons + bank interest at the derived rate + principal at each maturity | D34: ='Cash flow'!$F$40 -> 1040 | E34: The figure shown is annual profit and interest, which ties exactly to the finance cost the company reported. Principal is repaid gross, with refinancing proceeds shown separately when the toggle is on.
A35: Test the cash | B35: Cash flow F94:F101 | C35: modelled cash in the maturity month, before that principal is paid ÷ the principal then due | D35: =SUM('Cash flow'!$G$94:$G$101) -> 550.97944 | E35: Measure B, and the binding answer. The figure shown is the total modelled shortfall in AED m, all of it falling before March 2027. This is what the Cover reports.
A37: 3. CONVENTIONS
A38: Blue text | B38: An input. Yours to change.
A39: Black text | B39: A formula calculated on the same sheet.
A40: Green text | B40: Pulled from another sheet in this workbook.
A41: Yellow fill | B41: A key assumption that deserves your attention.
A42: Orange fill | B42: A caveat or a threshold breach.
A43: Grouped columns | B43: Simulator columns AY to BZ carry the four-scenario engine. They are grouped, not hidden: use the plus and minus toggle above the column letters.
A44: Units | B44: AED millions throughout, except average ticket (AED) and certified progress (percentage points, 0–100 not 0–1).
...

Sheet Dashboard
A1: Binghatti Holding — liquidity against maturities, from the register
A2: Can the escrow release from towers under construction, plus the cash the company holds outside escrow, meet the debt falling due? Every number below is a register fact, a filed figure, or arithmetic on the scenario inputs. DPI expresses no view.
A3: As of | B3: =Simulator!$C$3 -> 46275
A4: Active scenario | B4: =Scenarios!$C$3 -> Base | C4: change on the Scenarios sheet, cell B3
A5: Cash outside escrow, AED m (30 Jun 2026) | B5: =Financials!D19 -> 394 | C5: plus received since, AED m: | D5: ='Handover check'!B28 -> 292.5759 | E5: =_xlfn._LONGTEXT("Cash received after the 30 Jun 2026 balance sheet date, which the opening balance cannot see. The AED 1.8 bn attributed to three handovers is unsourced. Tested against the register on the Handover check tab: one confirmed handover, Binghatti Pinnacle, sup","porting AED ")&TEXT('Handover check'!$B$28,"#,##0")&" m. That figure is entered here. Entering 1,800 instead would remove the shortfall entirely." -> Cash received after the 30 Jun 2026 balance sheet date, which the opening balance cannot see. The AED 1.8 bn attributed to three handovers is unsourced. Tested against the register on the Handover check tab: one confirmed handover, Binghatti Pinnacle, supporting AED 293 m. That figure is entered here. Entering 1,800 instead would remove the shortfall entirely.
A6: Legend | B6: blue = input you can change | D6: green = pulled from another sheet
A8: THE VERDICT — CAN EACH MATURITY BE MET FROM CASH?
A9: {=_xlfn.LET(_xlpm.n,$E$12,_xlpm.g,$F$12,_xlpm.c,$C$12,_xlpm.lastd,MAX(('Cash flow'!$G$94:$G$101>0)*'Cash flow'!$B$94:$B$101),IF(_xlpm.n=0,"On the "&$G$12&" case every maturity to 2031 is met from modelled cash, the 9.625% sukuk due 28 February 2027 covered "&TEXT(_xlpm.c,"0.00")&" times over. Conditional on the three assumptions listed on the Cover.","On the "&$G$12&" case and the register as it stands, the 9.625% sukuk due 28 February 2027 is not met from modelled cash: "&TEXT(_xlpm.c,"0.00")&"x, short AED "&TEXT($D$12,"#,##0")&" m. "&_xlpm.n&" of the eight maturities to 2031 fall short, AED "&TEXT(_xlpm.g,"#,##0")&" m in total, the last maturing "&TEXT(_xlpm.lastd,"mmm yyyy")&". Treat this as conditional: three derived assumptions, listed on the Cover, each reverse it on their own."))} -> On the Base case and the register as it stands, the 9.625% sukuk due 28 February 2027 is not met from modelled cash: 0.80x, short AED 363 m. 2 of the eight maturities to 2031 fall short, AED 551 m in total, the last maturing Feb 2027. Treat this as conditional: three derived assumptions, listed on the Cover, each reverse it on their own.
A11: Principal due 28 Feb 2027 | B11: Cash available then | C11: Coverage, cash test | D11: Shortfall on that sukuk | E11: Maturities short, of eight | F11: Total shortfall to 2031 | G11: Active scenario
A12: ='Cash flow'!$C$94 -> 1836.25 | B12: ='Cash flow'!$E$94 -> 1473.7013 | C12: ='Cash flow'!$F$94 -> 0.80256025 | D12: ='Cash flow'!$G$94 -> 362.54875 | E12: =COUNTIF('Cash flow'!$F$94:$F$101,"<1") -> 2 | F12: =SUM('Cash flow'!$G$94:$G$101) -> 550.97944 | G12: =$B$4 -> Base
A13: ="Section 1 below is a different and weaker measure: escrow release against debt, before construction cost and debt service. On that basis the February sukuk reads "&TEXT($F$17,"0.00")&"x. It is a headroom diagnostic, useful for ranking scenarios, and it is not the repayment test. The cash test above and on the Cover is what binds." -> Section 1 below is a different and weaker measure: escrow release against debt, before construction cost and debt service. On that basis the February sukuk reads 3.79x. It is a headroom diagnostic, useful for ranking scenarios, and it is not the repayment test. The cash test above and on the Cover is what binds. | I13: CHART DATA — formulas only, no new inputs
A15: 1. ESCROW HEADROOM BY MATURITY DATE, ALL FOUR SCENARIOS — BEFORE CONSTRUCTION COST AND DEBT SERVICE | I15: Scenario | J15: Coverage at 28 Feb 2027
A16: Date | B16: Debt due by then (AED m) | C16: Cash outside escrow + received | D16: Scenario | E16: Modelled escrow release by then | F16: Headroom (x) | G16: Gap on this measure (AED m) | I16: =$D$17 -> Base | J16: =$F$17 -> 3.7916279
A17: 28 Feb 2027 — 9.625% sukuk | B17: =SUMIFS(Debt!$E$6:$E$13,Debt!$H$6:$H$13,"<="&DATE(2027,2,28)) -> 2868.2225 | C17: =$B$5+$D$5 -> 686.5759 | D17: Base | E17: =Simulator!BC40 -> 10188.657 | F17: =IF(B17>0,(C17+E17)/B17,"") -> 3.7916279 | G17: =MAX(0,B17-C17-E17) -> 0 | I17: =$D$18 -> Delayed handovers | J17: =$F$18 -> 2.1844842
B18: =SUMIFS(Debt!$E$6:$E$13,Debt!$H$6:$H$13,"<="&DATE(2027,2,28)) -> 2868.2225 | C18: =$B$5+$D$5 -> 686.5759 | D18: Delayed handovers | E18: =Simulator!BJ40 -> 5579.0108 | F18: =IF(B18>0,(C18+E18)/B18,"") -> 2.1844842 | G18: =MAX(0,B18-C18-E18) -> 0 | I18: =$D$19 -> Cancellation spike | J18: =$F$19 -> 2.9663109
B19: =SUMIFS(Debt!$E$6:$E$13,Debt!$H$6:$H$13,"<="&DATE(2027,2,28)) -> 2868.2225 | C19: =$B$5+$D$5 -> 686.5759 | D19: Cancellation spike | E19: =Simulator!BQ40 -> 7821.4639 | F19: =IF(B19>0,(C19+E19)/B19,"") -> 2.9663109 | G19: =MAX(0,B19-C19-E19) -> 0 | I19: =$D$20 -> Price cut | J19: =$F$20 -> 3.4916259
B20: =SUMIFS(Debt!$E$6:$E$13,Debt!$H$6:$H$13,"<="&DATE(2027,2,28)) -> 2868.2225 | C20: =$B$5+$D$5 -> 686.5759 | D20: Price cut | E20: =Simulator!BX40 -> 9328.184 | F20: =IF(B20>0,(C20+E20)/B20,"") -> 3.4916259 | G20: =MAX(0,B20-C20-E20) -> 0
A21: 31 Dec 2027 | B21: =SUMIFS(Debt!$E$6:$E$13,Debt!$H$6:$H$13,"<="&DATE(2027,12,31)) -> 4741.1975 | C21: =$B$5+$D$5 -> 686.5759 | D21: Base | E21: =Simulator!BD40 -> 32644.325 | F21: =IF(B21>0,(C21+E21)/B21,"") -> 7.0300595 | G21: =MAX(0,B21-C21-E21) -> 0
B22: =SUMIFS(Debt!$E$6:$E$13,Debt!$H$6:$H$13,"<="&DATE(2027,12,31)) -> 4741.1975 | C22: =$B$5+$D$5 -> 686.5759 | D22: Delayed handovers | E22: =Simulator!BK40 -> 28475.065 | F22: =IF(B22>0,(C22+E22)/B22,"") -> 6.1506909 | G22: =MAX(0,B22-C22-E22) -> 0 | I22: Delay (months) | J22: No cancellations | K22: 15% cancellations
B23: =SUMIFS(Debt!$E$6:$E$13,Debt!$H$6:$H$13,"<="&DATE(2027,12,31)) -> 4741.1975 | C23: =$B$5+$D$5 -> 686.5759 | D23: Cancellation spike | E23: =Simulator!BR40 -> 26501.314 | F23: =IF(B23>0,(C23+E23)/B23,"") -> 5.7343931 | G23: =MAX(0,B23-C23-E23) -> 0 | I23: ='Break-even'!$B$36 -> 0 | J23: ='Break-even'!$C$36 -> 3.7916279 | K23: ='Break-even'!$F$36 -> 3.1277083
B24: =SUMIFS(Debt!$E$6:$E$13,Debt!$H$6:$H$13,"<="&DATE(2027,12,31)) -> 4741.1975 | C24: =$B$5+$D$5 -> 686.5759 | D24: Price cut | E24: =Simulator!BY40 -> 30464.424 | F24: =IF(B24>0,(C24+E24)/B24,"") -> 6.5702811 | G24: =MAX(0,B24-C24-E24) -> 0 | I24: ='Break-even'!$B$37 -> 5 | J24: ='Break-even'!$C$37 -> 2.7709491 | K24: ='Break-even'!$F$37 -> 2.2433021
A25: 31 Dec 2028 | B25: =SUMIFS(Debt!$E$6:$E$13,Debt!$H$6:$H$13,"<="&DATE(2028,12,31)) -> 6114.7125 | C25: =$B$5+$D$5 -> 686.5759 | D25: Base | E25: =Simulator!BE40 -> 34786.092 | F25: =IF(B25>0,(C25+E25)/B25,"") -> 5.8011996 | G25: =MAX(0,B25-C25-E25) -> 0 | I25: ='Break-even'!$B$38 -> 10 | J25: ='Break-even'!$C$38 -> 1.9757644 | K25: ='Break-even'!$F$38 -> 1.5555883
B26: =SUMIFS(Debt!$E$6:$E$13,Debt!$H$6:$H$13,"<="&DATE(2028,12,31)) -> 6114.7125 | C26: =$B$5+$D$5 -> 686.5759 | D26: Delayed handovers | E26: =Simulator!BL40 -> 32269.986 | F26: =IF(B26>0,(C26+E26)/B26,"") -> 5.3897156 | G26: =MAX(0,B26-C26-E26) -> 0 | I26: ='Break-even'!$B$39 -> 15 | J26: ='Break-even'!$C$39 -> 1.4956877 | K26: ='Break-even'!$F$39 -> 1.1410835
B27: =SUMIFS(Debt!$E$6:$E$13,Debt!$H$6:$H$13,"<="&DATE(2028,12,31)) -> 6114.7125 | C27: =$B$5+$D$5 -> 686.5759 | D27: Cancellation spike | E27: =Simulator!BS40 -> 28313.568 | F27: =IF(B27>0,(C27+E27)/B27,"") -> 4.7426832 | G27: =MAX(0,B27-C27-E27) -> 0 | I27: ='Break-even'!$B$40 -> 20 | J27: ='Break-even'!$C$40 -> 1.238056 | K27: ='Break-even'!$F$40 -> 0.92079571
B28: =SUMIFS(Debt!$E$6:$E$13,Debt!$H$6:$H$13,"<="&DATE(2028,12,31)) -> 6114.7125 | C28: =$B$5+$D$5 -> 686.5759 | D28: Price cut | E28: =Simulator!BZ40 -> 32494.604 | F28: =IF(B28>0,(C28+E28)/B28,"") -> 5.4264498 | G28: =MAX(0,B28-C28-E28) -> 0 | I28: ='Break-even'!$B$41 -> 25 | J28: ='Break-even'!$C$41 -> 1.0774232 | K28: ='Break-even'!$F$41 -> 0.78464204
A29: =_xlfn._LONGTEXT("This section is the headroom measure, not the cash test. Debt due is cumulative from today to the date shown, so the Feb-2027 line includes the bank debt the accounts place in H2 2026. Headroom above 1.0x means modelled escrow release plus free cash excee","ds what is due, before any deduction for building the towers or servicing the debt. On the cash test the same February maturity reads ")&TEXT($C$12,"0.00")&"x. Use this section to compare scenarios; use the Cash flow sheet to answer whether a maturity can be paid." -> This section is the headroom measure, not the cash test. Debt due is cumulative from today to the date shown, so the Feb-2027 line includes the bank debt the accounts place in H2 2026. Headroom above 1.0x means modelled escrow release plus free cash exceeds what is due, before any deduction for building the towers or servicing the debt. On the cash test the same February maturity reads 0.80x. Use this section to compare scenarios; use the Cash flow sheet to answer whether a maturity can be paid. | I29: ='Break-even'!$B$42 -> 30 | J29: ='Break-even'!$C$42 -> 0.96774187 | K29: ='Break-even'!$F$42 -> 0.69176633
A32: 2. Monthly escrow release, active scenario (AED m)
A33: Month | B33: Cumulative release | C33: In the month | D33: Debt falling due in the month | E33: Running cash after debt (from free cash) | I33: Month | J33: Cumulative escrow release | K33: Cumulative debt due | L33: Cash net
A34: 46296 | B34: =Simulator!V40 -> 1771.9373 | C34: =Simulator!V41 -> 1771.9373 | D34: =SUMPRODUCT((YEAR(Debt!$H$6:$H$13)=2026)*(MONTH(Debt!$H$6:$H$13)=10)*Debt!$E$6:$E$13) -> 0 | E34: =$B$5+$D$5+B34-SUM($D$34:D34) -> 2458.5132 | I34: =$A34 -> 46296 | J34: =$B34 -> 1771.9373 | K34: =SUM($D$34:$D34) -> 0 | L34: =INDEX('Cash flow'!$C$71:$BN$71,MATCH($I34,'Cash flow'!$C$58:$BN$58,0)) -> 768.98975
A35: 46327 | B35: =Simulator!W40 -> 3371.8109 | C35: =Simulator!W41 -> 1599.8736 | D35: =SUMPRODUCT((YEAR(Debt!$H$6:$H$13)=2026)*(MONTH(Debt!$H$6:$H$13)=11)*Debt!$E$6:$E$13) -> 0 | E35: =$B$5+$D$5+B35-SUM($D$34:D35) -> 4058.3868 | I35: =$A35 -> 46327 | J35: =$B35 -> 3371.8109 | K35: =SUM($D$34:$D35) -> 0 | L35: =INDEX('Cash flow'!$C$71:$BN$71,MATCH($I35,'Cash flow'!$C$58:$BN$58,0)) -> 679.3399
A36: 46357 | B36: =Simulator!X40 -> 5225.5363 | C36: =Simulator!X41 -> 1853.7254 | D36: =SUMPRODUCT((YEAR(Debt!$H$6:$H$13)=2026)*(MONTH(Debt!$H$6:$H$13)=12)*Debt!$E$6:$E$13) -> 1031.9725 | E36: =$B$5+$D$5+B36-SUM($D$34:D36) -> 4880.1397 | I36: =$A36 -> 46357 | J36: =$B36 -> 5225.5363 | K36: =SUM($D$34:$D36) -> 1031.9725 | L36: =INDEX('Cash flow'!$C$71:$BN$71,MATCH($I36,'Cash flow'!$C$58:$BN$58,0)) -> -188.43069
A37: 46388 | B37: =Simulator!Y40 -> 7333.1135 | C37: =Simulator!Y41 -> 2107.5771 | D37: =SUMPRODUCT((YEAR(Debt!$H$6:$H$13)=2027)*(MONTH(Debt!$H$6:$H$13)=1)*Debt!$E$6:$E$13) -> 0 | E37: =$B$5+$D$5+B37-SUM($D$34:D37) -> 6987.7169 | I37: =$A37 -> 46388 | J37: =$B37 -> 7333.1135 | K37: =SUM($D$34:$D37) -> 1031.9725 | L37: =INDEX('Cash flow'!$C$71:$BN$71,MATCH($I37,'Cash flow'!$C$58:$BN$58,0)) -> 238.02424
A38: 46419 | B38: =Simulator!Z40 -> 10188.657 | C38: =Simulator!Z41 -> 2855.5431 | D38: =SUMPRODUCT((YEAR(Debt!$H$6:$H$13)=2027)*(MONTH(Debt!$H$6:$H$13)=2)*Debt!$E$6:$E$13) -> 1836.25 | E38: =$B$5+$D$5+B38-SUM($D$34:D38) -> 8007.01 | I38: =$A38 -> 46419 | J38: =$B38 -> 10188.657 | K38: =SUM($D$34:$D38) -> 2868.2225 | L38: =INDEX('Cash flow'!$C$71:$BN$71,MATCH($I38,'Cash flow'!$C$58:$BN$58,0)) -> -362.54875
A39: 46447 | B39: =Simulator!AA40 -> 13785.522 | C39: =Simulator!AA41 -> 3596.8651 | D39: =SUMPRODUCT((YEAR(Debt!$H$6:$H$13)=2027)*(MONTH(Debt!$H$6:$H$13)=3)*Debt!$E$6:$E$13) -> 0 | E39: =$B$5+$D$5+B39-SUM($D$34:D39) -> 11603.875 | I39: =$A39 -> 46447 | J39: =$B39 -> 13785.522 | K39: =SUM($D$34:$D39) -> 2868.2225 | L39: =INDEX('Cash flow'!$C$71:$BN$71,MATCH($I39,'Cash flow'!$C$58:$BN$58,0)) -> 1665.9322
A40: 46478 | B40: =Simulator!AB40 -> 16841.512 | C40: =Simulator!AB41 -> 3055.9904 | D40: =SUMPRODUCT((YEAR(Debt!$H$6:$H$13)=2027)*(MONTH(Debt!$H$6:$H$13)=4)*Debt!$E$6:$E$13) -> 0 | E40: =$B$5+$D$5+B40-SUM($D$34:D40) -> 14659.865 | I40: =$A40 -> 46478 | J40: =$B40 -> 16841.512 | K40: =SUM($D$34:$D40) -> 2868.2225 | L40: =INDEX('Cash flow'!$C$71:$BN$71,MATCH($I40,'Cash flow'!$C$58:$BN$58,0)) -> 3338.8422
A41: 46508 | B41: =Simulator!AC40 -> 19403.154 | C41: =Simulator!AC41 -> 2561.6423 | D41: =SUMPRODUCT((YEAR(Debt!$H$6:$H$13)=2027)*(MONTH(Debt!$H$6:$H$13)=5)*Debt!$E$6:$E$13) -> 0 | E41: =$B$5+$D$5+B41-SUM($D$34:D41) -> 17221.508 | I41: =$A41 -> 46508 | J41: =$B41 -> 19403.154 | K41: =SUM($D$34:$D41) -> 2868.2225 | L41: =INDEX('Cash flow'!$C$71:$BN$71,MATCH($I41,'Cash flow'!$C$58:$BN$58,0)) -> 4579.8307
A42: 46539 | B42: =Simulator!AD40 -> 23171.799 | C42: =Simulator!AD41 -> 3768.6449 | D42: =SUMPRODUCT((YEAR(Debt!$H$6:$H$13)=2027)*(MONTH(Debt!$H$6:$H$13)=6)*Debt!$E$6:$E$13) -> 690.43 | E42: =$B$5+$D$5+B42-SUM($D$34:D42) -> 20299.723 | I42: =$A42 -> 46539 | J42: =$B42 -> 23171.799 | K42: =SUM($D$34:$D42) -> 3558.6525 | L42: =INDEX('Cash flow'!$C$71:$BN$71,MATCH($I42,'Cash flow'!$C$58:$BN$58,0)) -> 6554.1814
A43: 46569 | B43: =Simulator!AE40 -> 28729.544 | C43: =Simulator!AE41 -> 5557.7445 | D43: =SUMPRODUCT((YEAR(Debt!$H$6:$H$13)=2027)*(MONTH(Debt!$H$6:$H$13)=7)*Debt!$E$6:$E$13) -> 0 | E43: =$B$5+$D$5+B43-SUM($D$34:D43) -> 25857.467 | I43: =$A43 -> 46569 | J43: =$B43 -> 28729.544 | K43: =SUM($D$34:$D43) -> 3558.6525 | L43: =INDEX('Cash flow'!$C$71:$BN$71,MATCH($I43,'Cash flow'!$C$58:$BN$58,0)) -> 11190.92
A44: 46600 | B44: =Simulator!AF40 -> 29440.238 | C44: =Simulator!AF41 -> 710.69414 | D44: =SUMPRODUCT((YEAR(Debt!$H$6:$H$13)=2027)*(MONTH(Debt!$H$6:$H$13)=8)*Debt!$E$6:$E$13) -> 0 | E44: =$B$5+$D$5+B44-SUM($D$34:D44) -> 26568.161 | I44: =$A44 -> 46600 | J44: =$B44 -> 29440.238 | K44: =SUM($D$34:$D44) -> 3558.6525 | L44: =INDEX('Cash flow'!$C$71:$BN$71,MATCH($I44,'Cash flow'!$C$58:$BN$58,0)) -> 11515.358
A45: 46631 | B45: =Simulator!AG40 -> 30069.004 | C45: =Simulator!AG41 -> 628.76576 | D45: =SUMPRODUCT((YEAR(Debt!$H$6:$H$13)=2027)*(MONTH(Debt!$H$6:$H$13)=9)*Debt!$E$6:$E$13) -> 0 | E45: =$B$5+$D$5+B45-SUM($D$34:D45) -> 27196.927 | I45: =$A45 -> 46631 | J45: =$B45 -> 30069.004 | K45: =SUM($D$34:$D45) -> 3558.6525 | L45: =INDEX('Cash flow'!$C$71:$BN$71,MATCH($I45,'Cash flow'!$C$58:$BN$58,0)) -> 11760.234
...

Sheet Break-even
A1: BREAK-EVEN — HOW FAR CAN HANDOVERS SLIP BEFORE ESCROW HEADROOM FAILS?
A2: February 2027 escrow headroom across a grid of handover delay against cancellation rate, independent of whichever scenario is active. Headroom is escrow release plus free cash against debt due, before construction cost and debt service. For whether the maturity can actually be paid, see the cash test above and the Cash flow sheet.
A4: 1. WHAT THIS SHEET DOES
A5: It re-runs the escrow model from first principles for every combination of two variables, and reports the resulting coverage of the 28 February 2027 maturity. Everything else is held at the Base column of the Scenarios sheet, so switching the active scenario does not move this grid.
A6: One difference from the Scenarios delay input: there, delay shifts only registered completion dates, so towers whose date has already passed are unaffected. Here delay shifts every tower, including those on the fallback runway. That makes the axis a genuine stress rather than one that leaves part of the portfolio immune.
A7: 2. THE CASH TEST — READ THIS BEFORE THE GRID BELOW
A8: This sheet measures escrow headroom: escrow release plus free cash against debt due, before the cost of building the towers and before debt service. On that measure the February 2027 sukuk does not fail until handovers slip a long way. On the cash test, which deducts both and is the binding answer on the Cover and the Cash flow sheet, it is already short today. Both numbers are shown here so the sheet cannot be read in isolation.
A9: Measure | B9: Value | C9: Note
A10: Escrow headroom, 28 Feb 2027 (this sheet, base corner) | B10: =$C$36 -> 3.7916279 | C10: The top-left cell of the grid below. Ties to Dashboard section 1.
A11: Cash-test coverage, 28 Feb 2027 | B11: ='Cash flow'!$F$94 -> 0.80256025 | C11: After construction cost and debt service. This is the binding measure.
A12: Cash-test shortfall on that sukuk | B12: ='Cash flow'!$G$94 -> 362.54875 | C12: AED m. New money, an asset sale or a refinancing of this size closes it.
A13: Cost to complete that would bring the cash test to 1.00x | B13: =IF('Cash flow'!$G$63>0,Scenarios!$F$15-'Cash flow'!$G$94/('Cash flow'!$G$63/Scenarios!$F$15),"") -> 0.52492756 | C13: ="Against "&TEXT(Scenarios!$F$15,"0.0%")&" assumed. Cost is the one input that flips the answer within a few percentage points, which is why it is the first thing to replace with real data." -> Against 55.0% assumed. Cost is the one input that flips the answer within a few percentage points, which is why it is the first thing to replace with real data.
A14: Handover delay that breaks the headroom measure | B14: =$B$45 -> 28.529461 | C14: Months. This is the grid's answer, on the weaker measure. It does not mean the February sukuk is safe for that long.
A16: 3. HELD FIXED
A17: Input | B17: Value | C17: Source
A18: Sell-through of unsold units | B18: =Scenarios!$B$9 -> 0.6 | C18: Scenarios, Base column
A19: Price change on future sales | B19: =Scenarios!$B$10 -> 0 | C19: Scenarios, Base column
A20: Share collected at booking | B20: =Scenarios!$B$11 -> 0.1 | C20: Scenarios, Base column
A21: Share collected at handover | B21: =Scenarios!$B$12 -> 0.3 | C21: Scenarios, Base column
A22: RERA escrow retention | B22: =Scenarios!$B$13 -> 0.05 | C22: Scenarios, Base column
A23: Maximum certified progress per month (pts) | B23: =Scenarios!$B$14 -> 8 | C23: Scenarios, Base column
A24: Runway for towers past their registered date (months) | B24: =Scenarios!$B$6 -> 6 | C24: Scenarios, Base column
A25: Runway for towers with no registered date (months) | B25: =Scenarios!$B$7 -> 24 | C25: Scenarios, Base column
A26: Register read date | B26: =Simulator!$C$3 -> 46275 | C26: Simulator
A27: Checkpoint — months after read date | B27: 5 | C27: Month 5 of the grid is February 2027
A28: Cash outside escrow, plus any received | B28: =Dashboard!$C$17 -> 686.5759 | C28: Dashboard
A29: Debt due by 28 Feb 2027 | B29: =Dashboard!$B$17 -> 2868.2225 | C29: Debt, instruments dated on or before 28 Feb 2027
A32: 4. FEBRUARY 2027 ESCROW HEADROOM GRID
A33: Escrow headroom on the 28 February 2027 maturity. Cells at or below 1.00x mean escrow release plus free cash no longer covers the debt due even before construction cost. The top-left cell is the Base case and ties exactly to Dashboard section 1. Remember that on the cash test this maturity is already below 1.00x at zero delay.
B35: Delay (months) \ Cancellation rate | C35: 0 | D35: 0.05 | E35: 0.1 | F35: 0.15 | G35: 0.2 | H35: 0.25 | I35: 0.3
B36: 0 | C36: {=_xlfn.LET(_xlpm.rf,INDEX($F$57:$L$88,0,MATCH($B36,$F$56:$L$56,0)),_xlpm.x,($C$57:$C$88*(1-C$35)+$D$57:$D$88)*_xlpm.rf-$E$57:$E$88,_xlpm.rel,SUMPRODUCT(_xlpm.x*(_xlpm.x>0)),($B$28+_xlpm.rel)/$B$29)} -> 3.7916279 | D36: {=_xlfn.LET(_xlpm.rf,INDEX($F$57:$L$88,0,MATCH($B36,$F$56:$L$56,0)),_xlpm.x,($C$57:$C$88*(1-D$35)+$D$57:$D$88)*_xlpm.rf-$E$57:$E$88,_xlpm.rel,SUMPRODUCT(_xlpm.x*(_xlpm.x>0)),($B$28+_xlpm.rel)/$B$29)} -> 3.5666075 | E36: {=_xlfn.LET(_xlpm.rf,INDEX($F$57:$L$88,0,MATCH($B36,$F$56:$L$56,0)),_xlpm.x,($C$57:$C$88*(1-E$35)+$D$57:$D$88)*_xlpm.rf-$E$57:$E$88,_xlpm.rel,SUMPRODUCT(_xlpm.x*(_xlpm.x>0)),($B$28+_xlpm.rel)/$B$29)} -> 3.3427603 | F36: {=_xlfn.LET(_xlpm.rf,INDEX($F$57:$L$88,0,MATCH($B36,$F$56:$L$56,0)),_xlpm.x,($C$57:$C$88*(1-F$35)+$D$57:$D$88)*_xlpm.rf-$E$57:$E$88,_xlpm.rel,SUMPRODUCT(_xlpm.x*(_xlpm.x>0)),($B$28+_xlpm.rel)/$B$29)} -> 3.1277083 | G36: {=_xlfn.LET(_xlpm.rf,INDEX($F$57:$L$88,0,MATCH($B36,$F$56:$L$56,0)),_xlpm.x,($C$57:$C$88*(1-G$35)+$D$57:$D$88)*_xlpm.rf-$E$57:$E$88,_xlpm.rel,SUMPRODUCT(_xlpm.x*(_xlpm.x>0)),($B$28+_xlpm.rel)/$B$29)} -> 2.9126563 | H36: {=_xlfn.LET(_xlpm.rf,INDEX($F$57:$L$88,0,MATCH($B36,$F$56:$L$56,0)),_xlpm.x,($C$57:$C$88*(1-H$35)+$D$57:$D$88)*_xlpm.rf-$E$57:$E$88,_xlpm.rel,SUMPRODUCT(_xlpm.x*(_xlpm.x>0)),($B$28+_xlpm.rel)/$B$29)} -> 2.6976043 | I36: {=_xlfn.LET(_xlpm.rf,INDEX($F$57:$L$88,0,MATCH($B36,$F$56:$L$56,0)),_xlpm.x,($C$57:$C$88*(1-I$35)+$D$57:$D$88)*_xlpm.rf-$E$57:$E$88,_xlpm.rel,SUMPRODUCT(_xlpm.x*(_xlpm.x>0)),($B$28+_xlpm.rel)/$B$29)} -> 2.4825523 | K36: 1.00x or below — modelled shortfall
B37: 5 | C37: {=_xlfn.LET(_xlpm.rf,INDEX($F$57:$L$88,0,MATCH($B37,$F$56:$L$56,0)),_xlpm.x,($C$57:$C$88*(1-C$35)+$D$57:$D$88)*_xlpm.rf-$E$57:$E$88,_xlpm.rel,SUMPRODUCT(_xlpm.x*(_xlpm.x>0)),($B$28+_xlpm.rel)/$B$29)} -> 2.7709491 | D37: {=_xlfn.LET(_xlpm.rf,INDEX($F$57:$L$88,0,MATCH($B37,$F$56:$L$56,0)),_xlpm.x,($C$57:$C$88*(1-D$35)+$D$57:$D$88)*_xlpm.rf-$E$57:$E$88,_xlpm.rel,SUMPRODUCT(_xlpm.x*(_xlpm.x>0)),($B$28+_xlpm.rel)/$B$29)} -> 2.5909188 | E37: {=_xlfn.LET(_xlpm.rf,INDEX($F$57:$L$88,0,MATCH($B37,$F$56:$L$56,0)),_xlpm.x,($C$57:$C$88*(1-E$35)+$D$57:$D$88)*_xlpm.rf-$E$57:$E$88,_xlpm.rel,SUMPRODUCT(_xlpm.x*(_xlpm.x>0)),($B$28+_xlpm.rel)/$B$29)} -> 2.4134341 | F37: {=_xlfn.LET(_xlpm.rf,INDEX($F$57:$L$88,0,MATCH($B37,$F$56:$L$56,0)),_xlpm.x,($C$57:$C$88*(1-F$35)+$D$57:$D$88)*_xlpm.rf-$E$57:$E$88,_xlpm.rel,SUMPRODUCT(_xlpm.x*(_xlpm.x>0)),($B$28+_xlpm.rel)/$B$29)} -> 2.2433021 | G37: {=_xlfn.LET(_xlpm.rf,INDEX($F$57:$L$88,0,MATCH($B37,$F$56:$L$56,0)),_xlpm.x,($C$57:$C$88*(1-G$35)+$D$57:$D$88)*_xlpm.rf-$E$57:$E$88,_xlpm.rel,SUMPRODUCT(_xlpm.x*(_xlpm.x>0)),($B$28+_xlpm.rel)/$B$29)} -> 2.0731701 | H37: {=_xlfn.LET(_xlpm.rf,INDEX($F$57:$L$88,0,MATCH($B37,$F$56:$L$56,0)),_xlpm.x,($C$57:$C$88*(1-H$35)+$D$57:$D$88)*_xlpm.rf-$E$57:$E$88,_xlpm.rel,SUMPRODUCT(_xlpm.x*(_xlpm.x>0)),($B$28+_xlpm.rel)/$B$29)} -> 1.9069999 | I37: {=_xlfn.LET(_xlpm.rf,INDEX($F$57:$L$88,0,MATCH($B37,$F$56:$L$56,0)),_xlpm.x,($C$57:$C$88*(1-I$35)+$D$57:$D$88)*_xlpm.rf-$E$57:$E$88,_xlpm.rel,SUMPRODUCT(_xlpm.x*(_xlpm.x>0)),($B$28+_xlpm.rel)/$B$29)} -> 1.7478787 | K37: 1.00x to 1.50x — tight
B38: 10 | C38: {=_xlfn.LET(_xlpm.rf,INDEX($F$57:$L$88,0,MATCH($B38,$F$56:$L$56,0)),_xlpm.x,($C$57:$C$88*(1-C$35)+$D$57:$D$88)*_xlpm.rf-$E$57:$E$88,_xlpm.rel,SUMPRODUCT(_xlpm.x*(_xlpm.x>0)),($B$28+_xlpm.rel)/$B$29)} -> 1.9757644 | D38: {=_xlfn.LET(_xlpm.rf,INDEX($F$57:$L$88,0,MATCH($B38,$F$56:$L$56,0)),_xlpm.x,($C$57:$C$88*(1-D$35)+$D$57:$D$88)*_xlpm.rf-$E$57:$E$88,_xlpm.rel,SUMPRODUCT(_xlpm.x*(_xlpm.x>0)),($B$28+_xlpm.rel)/$B$29)} -> 1.8313953 | E38: {=_xlfn.LET(_xlpm.rf,INDEX($F$57:$L$88,0,MATCH($B38,$F$56:$L$56,0)),_xlpm.x,($C$57:$C$88*(1-E$35)+$D$57:$D$88)*_xlpm.rf-$E$57:$E$88,_xlpm.rel,SUMPRODUCT(_xlpm.x*(_xlpm.x>0)),($B$28+_xlpm.rel)/$B$29)} -> 1.6900852 | F38: {=_xlfn.LET(_xlpm.rf,INDEX($F$57:$L$88,0,MATCH($B38,$F$56:$L$56,0)),_xlpm.x,($C$57:$C$88*(1-F$35)+$D$57:$D$88)*_xlpm.rf-$E$57:$E$88,_xlpm.rel,SUMPRODUCT(_xlpm.x*(_xlpm.x>0)),($B$28+_xlpm.rel)/$B$29)} -> 1.5555883 | G38: {=_xlfn.LET(_xlpm.rf,INDEX($F$57:$L$88,0,MATCH($B38,$F$56:$L$56,0)),_xlpm.x,($C$57:$C$88*(1-G$35)+$D$57:$D$88)*_xlpm.rf-$E$57:$E$88,_xlpm.rel,SUMPRODUCT(_xlpm.x*(_xlpm.x>0)),($B$28+_xlpm.rel)/$B$29)} -> 1.424231 | H38: {=_xlfn.LET(_xlpm.rf,INDEX($F$57:$L$88,0,MATCH($B38,$F$56:$L$56,0)),_xlpm.x,($C$57:$C$88*(1-H$35)+$D$57:$D$88)*_xlpm.rf-$E$57:$E$88,_xlpm.rel,SUMPRODUCT(_xlpm.x*(_xlpm.x>0)),($B$28+_xlpm.rel)/$B$29)} -> 1.3007349 | I38: {=_xlfn.LET(_xlpm.rf,INDEX($F$57:$L$88,0,MATCH($B38,$F$56:$L$56,0)),_xlpm.x,($C$57:$C$88*(1-I$35)+$D$57:$D$88)*_xlpm.rf-$E$57:$E$88,_xlpm.rel,SUMPRODUCT(_xlpm.x*(_xlpm.x>0)),($B$28+_xlpm.rel)/$B$29)} -> 1.1772387 | K38: above 1.50x — headroom
B39: 15 | C39: {=_xlfn.LET(_xlpm.rf,INDEX($F$57:$L$88,0,MATCH($B39,$F$56:$L$56,0)),_xlpm.x,($C$57:$C$88*(1-C$35)+$D$57:$D$88)*_xlpm.rf-$E$57:$E$88,_xlpm.rel,SUMPRODUCT(_xlpm.x*(_xlpm.x>0)),($B$28+_xlpm.rel)/$B$29)} -> 1.4956877 | D39: {=_xlfn.LET(_xlpm.rf,INDEX($F$57:$L$88,0,MATCH($B39,$F$56:$L$56,0)),_xlpm.x,($C$57:$C$88*(1-D$35)+$D$57:$D$88)*_xlpm.rf-$E$57:$E$88,_xlpm.rel,SUMPRODUCT(_xlpm.x*(_xlpm.x>0)),($B$28+_xlpm.rel)/$B$29)} -> 1.373091 | E39: {=_xlfn.LET(_xlpm.rf,INDEX($F$57:$L$88,0,MATCH($B39,$F$56:$L$56,0)),_xlpm.x,($C$57:$C$88*(1-E$35)+$D$57:$D$88)*_xlpm.rf-$E$57:$E$88,_xlpm.rel,SUMPRODUCT(_xlpm.x*(_xlpm.x>0)),($B$28+_xlpm.rel)/$B$29)} -> 1.2538219 | F39: {=_xlfn.LET(_xlpm.rf,INDEX($F$57:$L$88,0,MATCH($B39,$F$56:$L$56,0)),_xlpm.x,($C$57:$C$88*(1-F$35)+$D$57:$D$88)*_xlpm.rf-$E$57:$E$88,_xlpm.rel,SUMPRODUCT(_xlpm.x*(_xlpm.x>0)),($B$28+_xlpm.rel)/$B$29)} -> 1.1410835 | G39: {=_xlfn.LET(_xlpm.rf,INDEX($F$57:$L$88,0,MATCH($B39,$F$56:$L$56,0)),_xlpm.x,($C$57:$C$88*(1-G$35)+$D$57:$D$88)*_xlpm.rf-$E$57:$E$88,_xlpm.rel,SUMPRODUCT(_xlpm.x*(_xlpm.x>0)),($B$28+_xlpm.rel)/$B$29)} -> 1.0373765 | H39: {=_xlfn.LET(_xlpm.rf,INDEX($F$57:$L$88,0,MATCH($B39,$F$56:$L$56,0)),_xlpm.x,($C$57:$C$88*(1-H$35)+$D$57:$D$88)*_xlpm.rf-$E$57:$E$88,_xlpm.rel,SUMPRODUCT(_xlpm.x*(_xlpm.x>0)),($B$28+_xlpm.rel)/$B$29)} -> 0.93529373 | I39: {=_xlfn.LET(_xlpm.rf,INDEX($F$57:$L$88,0,MATCH($B39,$F$56:$L$56,0)),_xlpm.x,($C$57:$C$88*(1-I$35)+$D$57:$D$88)*_xlpm.rf-$E$57:$E$88,_xlpm.rel,SUMPRODUCT(_xlpm.x*(_xlpm.x>0)),($B$28+_xlpm.rel)/$B$29)} -> 0.8369517
B40: 20 | C40: {=_xlfn.LET(_xlpm.rf,INDEX($F$57:$L$88,0,MATCH($B40,$F$56:$L$56,0)),_xlpm.x,($C$57:$C$88*(1-C$35)+$D$57:$D$88)*_xlpm.rf-$E$57:$E$88,_xlpm.rel,SUMPRODUCT(_xlpm.x*(_xlpm.x>0)),($B$28+_xlpm.rel)/$B$29)} -> 1.238056 | D40: {=_xlfn.LET(_xlpm.rf,INDEX($F$57:$L$88,0,MATCH($B40,$F$56:$L$56,0)),_xlpm.x,($C$57:$C$88*(1-D$35)+$D$57:$D$88)*_xlpm.rf-$E$57:$E$88,_xlpm.rel,SUMPRODUCT(_xlpm.x*(_xlpm.x>0)),($B$28+_xlpm.rel)/$B$29)} -> 1.1271342 | E40: {=_xlfn.LET(_xlpm.rf,INDEX($F$57:$L$88,0,MATCH($B40,$F$56:$L$56,0)),_xlpm.x,($C$57:$C$88*(1-E$35)+$D$57:$D$88)*_xlpm.rf-$E$57:$E$88,_xlpm.rel,SUMPRODUCT(_xlpm.x*(_xlpm.x>0)),($B$28+_xlpm.rel)/$B$29)} -> 1.0197052 | F40: {=_xlfn.LET(_xlpm.rf,INDEX($F$57:$L$88,0,MATCH($B40,$F$56:$L$56,0)),_xlpm.x,($C$57:$C$88*(1-F$35)+$D$57:$D$88)*_xlpm.rf-$E$57:$E$88,_xlpm.rel,SUMPRODUCT(_xlpm.x*(_xlpm.x>0)),($B$28+_xlpm.rel)/$B$29)} -> 0.92079571 | G40: {=_xlfn.LET(_xlpm.rf,INDEX($F$57:$L$88,0,MATCH($B40,$F$56:$L$56,0)),_xlpm.x,($C$57:$C$88*(1-G$35)+$D$57:$D$88)*_xlpm.rf-$E$57:$E$88,_xlpm.rel,SUMPRODUCT(_xlpm.x*(_xlpm.x>0)),($B$28+_xlpm.rel)/$B$29)} -> 0.83016971 | H40: {=_xlfn.LET(_xlpm.rf,INDEX($F$57:$L$88,0,MATCH($B40,$F$56:$L$56,0)),_xlpm.x,($C$57:$C$88*(1-H$35)+$D$57:$D$88)*_xlpm.rf-$E$57:$E$88,_xlpm.rel,SUMPRODUCT(_xlpm.x*(_xlpm.x>0)),($B$28+_xlpm.rel)/$B$29)} -> 0.74157034 | I40: {=_xlfn.LET(_xlpm.rf,INDEX($F$57:$L$88,0,MATCH($B40,$F$56:$L$56,0)),_xlpm.x,($C$57:$C$88*(1-I$35)+$D$57:$D$88)*_xlpm.rf-$E$57:$E$88,_xlpm.rel,SUMPRODUCT(_xlpm.x*(_xlpm.x>0)),($B$28+_xlpm.rel)/$B$29)} -> 0.65990916
B41: 25 | C41: {=_xlfn.LET(_xlpm.rf,INDEX($F$57:$L$88,0,MATCH($B41,$F$56:$L$56,0)),_xlpm.x,($C$57:$C$88*(1-C$35)+$D$57:$D$88)*_xlpm.rf-$E$57:$E$88,_xlpm.rel,SUMPRODUCT(_xlpm.x*(_xlpm.x>0)),($B$28+_xlpm.rel)/$B$29)} -> 1.0774232 | D41: {=_xlfn.LET(_xlpm.rf,INDEX($F$57:$L$88,0,MATCH($B41,$F$56:$L$56,0)),_xlpm.x,($C$57:$C$88*(1-D$35)+$D$57:$D$88)*_xlpm.rf-$E$57:$E$88,_xlpm.rel,SUMPRODUCT(_xlpm.x*(_xlpm.x>0)),($B$28+_xlpm.rel)/$B$29)} -> 0.97377804 | E41: {=_xlfn.LET(_xlpm.rf,INDEX($F$57:$L$88,0,MATCH($B41,$F$56:$L$56,0)),_xlpm.x,($C$57:$C$88*(1-E$35)+$D$57:$D$88)*_xlpm.rf-$E$57:$E$88,_xlpm.rel,SUMPRODUCT(_xlpm.x*(_xlpm.x>0)),($B$28+_xlpm.rel)/$B$29)} -> 0.87373763 | F41: {=_xlfn.LET(_xlpm.rf,INDEX($F$57:$L$88,0,MATCH($B41,$F$56:$L$56,0)),_xlpm.x,($C$57:$C$88*(1-F$35)+$D$57:$D$88)*_xlpm.rf-$E$57:$E$88,_xlpm.rel,SUMPRODUCT(_xlpm.x*(_xlpm.x>0)),($B$28+_xlpm.rel)/$B$29)} -> 0.78464204 | G41: {=_xlfn.LET(_xlpm.rf,INDEX($F$57:$L$88,0,MATCH($B41,$F$56:$L$56,0)),_xlpm.x,($C$57:$C$88*(1-G$35)+$D$57:$D$88)*_xlpm.rf-$E$57:$E$88,_xlpm.rel,SUMPRODUCT(_xlpm.x*(_xlpm.x>0)),($B$28+_xlpm.rel)/$B$29)} -> 0.70114627 | H41: {=_xlfn.LET(_xlpm.rf,INDEX($F$57:$L$88,0,MATCH($B41,$F$56:$L$56,0)),_xlpm.x,($C$57:$C$88*(1-H$35)+$D$57:$D$88)*_xlpm.rf-$E$57:$E$88,_xlpm.rel,SUMPRODUCT(_xlpm.x*(_xlpm.x>0)),($B$28+_xlpm.rel)/$B$29)} -> 0.62458788 | I41: {=_xlfn.LET(_xlpm.rf,INDEX($F$57:$L$88,0,MATCH($B41,$F$56:$L$56,0)),_xlpm.x,($C$57:$C$88*(1-I$35)+$D$57:$D$88)*_xlpm.rf-$E$57:$E$88,_xlpm.rel,SUMPRODUCT(_xlpm.x*(_xlpm.x>0)),($B$28+_xlpm.rel)/$B$29)} -> 0.55207544
